Workbook

Sheet INFO
A1: AFC A-Z Budget FEATURE FILM
A2: Created June 2003
B3: Version F2 Dated: 14 June 2004
A4: INTRODUCTION AND INSTRUCTIONS FOR USE
A6: Welcome to the new format Budget - all contained within one workbook!
B7: THIS IS A BASE FORMAT - ADD OR DELETE CATEGORIES & LINE ITEMS AS REQUIRED
A9: DISCLAIMER
B10: The AFC have taken great care to ensure that the formulas in this budget are correct. However, as the formulas are not locked, errors can occur when numbers are entered to override formulas and/or when lines are added or subtracted. The AFC can take no responsibility for the accuracy of your budget. Please check each line where you have entered figures and ensure the accuracy of the sub totals and totals lines and columns.
A12: First - make sure you have selected the correct Budget base - the options are:
B13: Full Feature Film Short Documentary Interactive Digital Media Animation
A15: Second - fill out the Cover Sheet- BEFORE GOING INTO THE BUDGET OR WORKSHEET DETAIL
B16: The Summary Sheet will automatically fill from the Budget as you enter data
A18: Formulas have been included and therefore we are assuming reasonable Excel competence by users
A19: Notes are included throughout the Budget to assist you - see Column N - not printed
A20: If inserting or deleting rows, ensure you do it from the row numbers down the left hand column of the page
B21: otherwise the rest of the worksheet will move out of alignment.
A22: Do not delete columns. Column A of the Budget has been left blank to use for a Code reference if required.
A23: Unused lines and categories can be deleted
A24: If you delete a category, you will also need to delete its line in the Summary worksheet as #ref will appear
A26: If you do not want the zero values to show on your worksheets, delete as follows:
B27: Tools - Options - View - remove tick from Zero Values
A29: Use this budget format as a check list
A30: Change categories and cost items according to project needs or personal preferences
A31: Additional Worksheets can be included and linked: Insert - Worksheet
A33: If pages do not print on one sheet ( portrait or landscape) as formatted, change the scaling percentage:
B34: File - Page Setup - Page - Scaling - adjust to ..% (for each affected worksheet)
A35: If you find the font too small for working on a small screen, change the viewing size:
B36: View - Zoom - Custom - 120% or as required
B37: The budget font style is principally Arial Narrow -Size 9
B38: Change print areas if you wish to include Column A with a Cost Code.
A40: This workbook encompasses the following worksheets: (per coloured Tabs at bottom of page)
B41: Note: The coloured tabs are not supported by all versions of Excel
B42: INFO - This Introduction and instruction page
B43: Cover - detail of the production and budget assumptions
B44: Budget - A-Z detail (note new order of expense categories)
B45: Summary - of Budget (only print pages 1-2 for Australian $ cost)
B46: Breakdown sheets:
B47: 1 Development
B48: 2 Crew Overtime and Loadings - Budget Category C.24
B49: 3 Cast Fees and Fringes - Budget Categories D & E.2.3.4.5.
...

Sheet Cover
C3: TITLE: | D3: ShortKingz - Standard Production (~$55k) | O3: Title fills through to Summary & Budget
C4: PRODUCTION TYPE: | D4: Series - 60*1-2 min eps | O4: Describe/delete as appropriate
C5: STUDIO:
C6: PRODUCTION COMPANY:
C7: ABN: | F7: TFN:
C8: Address: | F8: T'phone: | I8: Fax:
F9: E-mail:
C10: DIRECTOR: | D10: Andrew Mills
C11: PRODUCER:
C13: LINE PRODUCER:
C15: SCRIPT Draft No. | D15: Date: 20 AUG 18
C16: REV. SCRIPT Draft No. | D16: Date:
C18: PRELIMINARY BUDGET: | D18: Date:
C19: REVISED BUDGET: | D19: Date:
C20: REVISED BUDGET: | D20: Date:
C21: FINAL BUDGET: | D21: Date: 20.8.18
C23: THIS BUDGET IS BASED ON THE FOLLOWING ASSUMPTIONS:
C24: Running Time estimate: | E24: Gauge: | G24: mm | H24: Tape: | I24: HDV
C25: Ratio: | D25: 0.50069444 | O25: To calculate main unit neg stock in Category I
C26: PREPRODUCTION: | E26: Start: | F26: 43479 | G26: Finish: | H26: 43497 | I26: Weeks: | K26: Days: | L26: 3
C27: SHOOT: | D27: 10 hr days/ 5day weeks. | E27: Start: | F27: 43500 | G27: Finish: | H27: 43509 | I27: Weeks: | K27: Days: | L27: 5 | O27: toBudget E.3 | Q27: to Worksheet 2-Crew O'time
C28: Travel Days: NB.incl.in Crew/Cast salaries. | E28: NIL
C29: Statutory Holidays: | E29: NIL
C30: 2ND UNIT: | E30: Start: | G30: Finish: | I30: Weeks: | K30: Days:
C31: POSTPRODUCTION 1: | D31: PIC | E31: Start: | F31: 43514 | G31: Finish: | H31: 43553 | I31: Weeks: | K31: Days: | L31: 5
C32: POSTPRODUCTION 2: | D32: SOUND | I32: Weeks: | K32: Days:
C35: LOCATION 1 | E35: From: | G35: To: | I35: Weeks: | K35: Days:
C36: LOCATION 2 | D36: OTHER | E36: From: | G36: To: | I36: Weeks: | K36: Days:
C37: LOCATION 3 | E37: From: | G37: To: | I37: Weeks: | K37: Days:
C38: STUDIO 1 | E38: From: | G38: To: | I38: Weeks: | K38: Days:
C39: STUDIO 2 | E39: From: | G39: To: | I39: Weeks: | K39: Days:
C40: STUDIO 3 | E40: From: | G40: To: | I40: Weeks: | K40: Days:
C42: CAST RATES: | F42: Daily | H42: Weekly
C43: minimum as at | D43: no. of hours | E43: 8 | F43: 267 | G43: 40 | H43: 1112 | N43: For current rates contact SPAA or MEAA
C44: Add: Category loading | E44: 0 | F44: =F43*E44 | H44: =H43*E44 | N44: NB - Deal structures for individual cast members
C45: Rights | E45: 0.7 | F45: =F43*E45 | H45: =H43*E45
C46: Overtime (10hr day/50hr wk) | D46: to no. hours | F46: =SUM(F43:F45)/E43*E46 | H46: =SUM(H43:H45)/G43*G46 | N46: Based on minimum plus loadings & rights
C47: Holiday Pay (10hr day/50hr wk) | E47: 12 | F47: =SUM(F43:F45)*8.33% | H47: =SUM(H43:H45)*8.33% | N47: Based on composite at 50 hrs plus overtime - check relevant Cast agreement
C48: = Minimum | F48: =SUM(F43:F47) | H48: =SUM(H43:H47)
C51: FRINGES & INSURANCE - RATES APPLIED:
...

Sheet Budget
A1: =Cover!D3 | F1: PRE-PRODN. | H1: SHOOT | J1: POST-PRODN. | L1: Sub-total | M1: T O T A L | N1: Notes:
C2: Description | D2: Rate | E2: Overtime portion (12-hour shoot days, 5 days) | F2: Wks | G2: Amount | H2: Wks | I2: Amount | J2: Wks | K2: Amount | N2: Lines 1&2 will appear at the top of each page
C3: NO. OF weeks SHOOT - | D3: =Cover!J27 | L3: Running total: | M3: =M284 | N3: Cell M.3 is the cumulative progressive total
A4: ABOVE THE LINE' COSTS | N4: If rows are added, ensure that formula is filled down
A5: A.1 | B5: STORY & SCRIPT | N5: All calculations are rounded to nearest dollar
C6: Writers Fees | D6: 900 | F6: 1 | G6: =D6*F6 | L6: =G6+I6+K6 | N6: Writer's Fees may also be in Development Funding
B7: Sub-total | G7: =SUM(G6) | I7: =SUM(I6) | K7: =SUM(K6) | L7: =G7+I7+K7 | N7: For all Category sub-totals Cell L must = Cell M
A8: A.2 | B8: DEVELOPMENT | N8: Development Funding - refer Worksheet 1
C9: Legal Expenses allow | F9: 1 | G9: =SUM(D9*F9)
B10: Sub-total | G10: =SUM(G9) | I10: =SUM(I9) | K10: =SUM(K9) | L10: =SUM(G10+I10+K10)
A12: A | C12: sub-total A | G12: =SUM(G10+G7) | L12: =SUM(L10+L7) | M12: =SUM(K12+I12+G12)
A13: B.1 | B13: PRODUCERS
C14: Executive Producer Fees | H14: 1 | I14: =SUM(H14*D14) | L14: =SUM(K14+I14+G14)
C15: Producer (Permanent) | D15: 1068.4 | E15: =((42.18*2)+(56.24*2.4))*5 | F15: 0.5 | G15: =D15*F15 | H15: 1 | I15: =H15*D15+E15*H15 | J15: 0.5 | K15: =J15*D15 | L15: =SUM(G15+I15+K15)
G16: =D16*F16 | H16: 1 | I16: =H16*D16+E16*H16 | K16: =J16*D16 | L16: =SUM(G16+I16)
C17: Holiday Pay & Fringes | L17: =SUM(G17+I17+K17) | N17: or include in D + W.Comp est.
B18: Sub-total | G18: =SUM(G15:G17) | I18: =SUM(I14:I17) | K18: =SUM(K15:K17) | L18: =SUM(L14:L17) | M18: =SUM(K18+I18+G18)
A19: B.2 | B19: DIRECTORS | N19: Split fees into Pre-prodn.,Shoot, Post-prodn per Contract
C20: Fees | N20: Assitant Directors - C3.
C21: Director (Permanent) | D21: 1198.5 | E21: =((47.31*2)+(63.08*2.4))*5 | F21: 0.5 | G21: =F21*D21 | H21: 1 | I21: =H21*D21+E21*H21 | J21: 0.3 | K21: =J21*D21 | L21: =G21+I21+K21 | N21: 2nd Unit Director - C19
G22: =F22*D22 | I22: =H22*D22 | K22: =J22*D22 | L22: =G22+I22+K22 | N22: or include in C.1
C23: Holiday Pay & Fringes | G23: =SUM(G21:G22)*0.1625 | I23: =SUM(I21:I22)*0.1625 | K23: =SUM(K21:K22)*0.1625 | L23: =G23+I23+K23 | N23: or include in D + W.Comp est.
G24: =SUM(G20:G23) | I24: =SUM(I20:I23) | K24: =SUM(K20:K23) | L24: =G24+I24+K24 | M24: =SUM(K24+I24+G24)
A26: B | B26: Sub-total | L26: =SUM(L12+L18+L24) | M26: =SUM(M24+M18+M12)
B28: TOTAL 'ABOVE THE LINE' COSTS | L28: =SUM(L24+L18+L12) | M28: =SUM(M24+M18+M12)
A29: BELOW THE LINE' COSTS
A30: PRODUCTION COSTS:
A31: C. | B31: PRODUCTION UNIT FEES & SALARIES. | N31: ALL OVERTIME - C.24
A32: C.1 | B32: PRODUCTION MANAGEMENT | N32: ALL HOL.PAY/SUPER/TAXES - D
C33: Production Manager | F33: 0 | G33: =D33*F33 | H33: 0 | I33: =H33*D33 | J33: 0 | K33: =J33*D33 | L33: =G33+I33+K33 | N33: from Cell E3 and some may need changing
C34: Production Co-ordinator | F34: 0 | G34: =D34*F34 | H34: 0 | I34: =H34*D34 | K34: =J34*D34 | L34: =G34+I34+K34
C35: Production Secretary | F35: 0 | G35: =D35*F35 | I35: =H35*D35 | J35: 0 | K35: =J35*D35 | L35: =G35+I35+K35 | N35: Postprodn Secretarial to R
C36: Runner(s) | F36: 0 | G36: =D36*F36 | H36: 0 | I36: =H36*D36 | J36: 0 | K36: =J36*D36 | L36: =G36+I36+K36
B37: Sub-total | G37: =SUM(G33:G36) | I37: =SUM(I33:I36) | K37: =SUM(K33:K36) | L37: =SUM(L33:L36) | M37: =SUM(K37+I37+G37)
A38: C.2 | B38: PRODUCTION ACCOUNTANCY
C39: Production Accountant | D39: 800 | F39: 0 | G39: =F39*D39 | H39: 0 | I39: =H39*D39 | J39: 0 | K39: =J39*D39 | L39: =G39+I39+K39 | N39: Postprodn Accounting may be budgeted in R
B40: Sub-total | G40: =SUM(G39) | I40: =SUM(I39) | K40: =SUM(K39) | L40: =SUM(L39) | M40: =SUM(K40+I40+G40)
A41: C.3 | B41: ASSISTANT DIRECTORS & SCRIPT SUPERVISION
C42: 1st Assistant Director (Casual) | D42: =1014.7*1.25 | E42: =((40.05*2*1.25)+(53.4*2.4*1.25))*5 | F42: 0.2 | G42: =F42*D42 | H42: 1 | I42: =H42*D42+E42*H42 | K42: =J42*D42 | L42: =G42+I42+K42
B43: Sub-total | G43: =SUM(G42) | I43: =SUM(I42) | K43: =SUM(K42) | L43: =SUM(L42) | M43: =SUM(K43+I43+G43)
...

Sheet 1.Dev
A1: 1. DEVELOPMENT FUNDING SCHEDULE - TO BUDGET CATEGORY A2
B2: Payments to: | C2: Name | D2: DEFERRALS | E2: FUNDING RECEIVED FOR: | N2: TOTALS
E3: 1st Draft | F3: 2nd Draft | G3: 3rd Draft | H3: 4th Draft | J3: Travel | K3: Casting | M3: GDI etc. Fellowships Matched funding
N5: =SUM(D5:M5)
B6: Producer | C6: stephen Luby | N6: =SUM(D6:M6)
N7: =SUM(D7:M7)
B8: Script Editor(s) | N8: =SUM(D8:M8)
B9: Composer | N9: =SUM(D9:M9)
N10: =SUM(D10:M10)
B11: Buyout Fees | N11: =SUM(D11:M11)
N12: =SUM(D12:M12)
B13: Script Typing & Copying | N13: =SUM(D13:M13)
B14: Schedules | N14: =SUM(D14:M14)
B15: Budgets | N15: =SUM(D15:M15)
B16: Consultancy Fees/Expenses | N16: =SUM(D16:M16)
B17: Research Expenses | N17: =SUM(D17:M17)
B18: Secretarial & Office Expenses | D18: - | N18: =SUM(D18:M18)
N19: =SUM(D19:M19)
B20: Location Surveys | N20: =SUM(D20:M20)
B21: Travel & Transport | N21: =SUM(D21:M21)
B22: Accommodation & Living Expenses | N22: =SUM(D22:M22)
N23: =SUM(D23:M23)
B24: Acting Workshop | N24: =SUM(D24:M24)
B25: Casting / Script Reading Fees | N25: =SUM(D25:M25)
B26: Preliminary Casting Fees / Expenses | N26: =SUM(D26:M26)
N27: =SUM(D27:M27)
B28: Legal Expenses | N28: =SUM(D28:M28)
B29: Overheads | N29: =SUM(D29:M29)
A30: Sub-total | B30: TOTAL | D30: =SUM(D5:D29) | E30: =SUM(E5:E29) | F30: =SUM(F5:F29) | G30: =SUM(G5:G29) | H30: =SUM(H5:H29) | I30: =SUM(I5:I29) | J30: =SUM(J5:J29) | K30: =SUM(K5:K29) | ... N30: =SUM(N5:N29)
B32: FUNDING SOURCE(S):
N33: =SUM(D33:M33)
N34: =SUM(D34:M34)
B35: Deferred | N35: =SUM(D35:M35)
N36: =SUM(D36:M36)
D37: =SUM(D33:D36) | E37: =SUM(E33:E36) | F37: =SUM(F33:F36) | G37: =SUM(G33:G36) | H37: =SUM(H33:H36) | I37: =SUM(I33:I36) | J37: =SUM(J33:J36) | K37: =SUM(K33:K36) | ... N37: =SUM(N33:N36)

Sheet 2.Crew
A1: 2. CREW OVERTIME AND LOADINGS SCHEDULE - TO BUDGET CATEGORY C24
A2: POSITION | B2: NAME/COMPANY | C2: Weekly Rate | D2: Hrly Rate | E2: Hrly Rate | F2: Dble time | G2: Triple time | H2: Regular overtime | J2: SHOOTING OVERTIME | N2: Total Shooting | O2: Estimate
C3: per contract | D3: shoot crew | E3: other crew | F3: rate $ | G3: rate $ | H3: Hrs. | I3: $ per day | J3: 1st hour | K3: 2nd hour | L3: 3rd hour | M3: 4th hour | N3: OVERTIME $ per day | O3: SHOOTING O'time | P3: NB. Refer notes rows 6-17
A4: Base per MPPA 2002 is Mon-Fri | C4: for … hr days | D4: divide D by: | F4: (after 10 hrs) | G4: (after 12 hrs) | N4: Total K-N | O4: No.days shoot | P4: from Cover sheet
A5: 5dayx10hr shoot= 50 hrs.(55 ord.hrs) | C5: & … day wks | D5: 55 | E5: for hrly rate | O5: =Cover!L27 | P5: or change to estimate.
A6: This is a complex spreadsheet but will deliver an accurate overtime costing if modified carefully. Complete the weekly rate in column D for all the crew that you have budgeted. Include casuals by dividing the total allowed
A7: for the shoot, divided by the no of shoot weeks eg if $2000 allowed for a 4 week shoot include $500 as the rate. This will calculate a low daily rate but should be reasonable when multiplied by total days of shoot. | P7: If you change regular overtime hours
A8: The shoot crew column E is used for the calculation of night shoots, public holidays and saturdays so should include all the people that you intend to work on such days and nights. You may change this default allocation | P8: change shooting O'time hour rates
B9: by copying the calculation into the appropriate column.
A10: The regular overtime column I is for all the hours per day that are worked by crew such as unit, ADs, continuity etc even on days when unit has wrapped in the contracted 10 hours. It is a daily cost. You may change this default
B11: however if you do you will need to change the formula in 1st and 2nd hour columns. Remember the first two hours after 10 are at double time and thereafter triple time.
B12: eg. If a unit assistant does 2 hrs regular o'time on a 10 hour day he will do 3 hours of uncontracted overtime on a 11 hour shooting day resulting in 1 hour of triple time.
A13: Delete all formulae where you do not want to allow overtime. eg. | D13: If you want to budget for one hour of overtime per day delete all the formulas in columns L-N.
D14: If you are not paying overtime to Dept. heads, delete the formulae in columns K-N for that crew member's row.
A15: You have now calculated the daily overtime. If you have completed number of days shoot on cover page this will fill in cell P5 and calculate total overtime in column P
A16: At the bottom a calculation will be made of night shoots, public holidays and saturdays. Fill in estimated number of night loaded hours Mon to Thur for entire shoot and Friday for entire shoot.
A17: Fill in number of public holidays and Saturdays (if a 6th day) to be budgeted through entire shoot. | F17: NB. Travel time may also apply | P17: NB. Determine if travel time will be required
A18: Producer's Assistant(s) | E18: =C18/D$5 | F18: =(D18+E18)*2 | G18: =(D18+E18)*3 | I18: =H18*F18 | J18: =F18 | K18: =F18 | L18: =G18 | M18: =G18 | N18: =SUM(J18:M18) | O18: =N18*O$5
A19: Director's Assistant | E19: =C19/D$5 | F19: =(D19+E19)*2 | G19: =(D19+E19)*3 | I19: =H19*F19 | J19: =F19 | K19: =F19 | L19: =G19 | M19: =G19 | N19: =SUM(J19:M19) | O19: =N19*O$5
A20: Production Supervisor | E20: =C20/D$5 | F20: =(D20+E20)*2 | G20: =(D20+E20)*3 | I20: =H20*F20 | J20: =F20 | K20: =F20 | L20: =G20 | M20: =G20 | N20: =SUM(J20:M20) | O20: =N20*O$5
A21: Production Manager | E21: =C21/D$5 | F21: =(D21+E21)*2 | G21: =(D21+E21)*3 | I21: =H21*F21 | J21: =F21 | K21: =F21 | L21: =G21 | M21: =G21 | N21: =SUM(J21:M21) | O21: =N21*O$5
A22: Production Co-ordinator | E22: =C22/D$5 | F22: =(D22+E22)*2 | G22: =(D22+E22)*3 | H22: 1 | I22: =H22*F22 | J22: =F22 | K22: =G22 | L22: =G22 | M22: =G22 | N22: =SUM(J22:M22) | O22: =N22*O$5
A23: Production Secretary | E23: =C23/D$5 | F23: =(D23+E23)*2 | G23: =(D23+E23)*3 | H23: 1 | I23: =H23*F23 | J23: =F23 | K23: =G23 | L23: =G23 | M23: =G23 | N23: =SUM(J23:M23) | O23: =N23*O$5
A24: Production Assistant(s) | E24: =C24/D$5 | F24: =(D24+E24)*2 | G24: =(D24+E24)*3 | H24: 1 | I24: =H24*F24 | J24: =F24 | K24: =G24 | L24: =G24 | M24: =G24 | N24: =SUM(J24:M24) | O24: =N24*O$5
A25: Runner(s) | E25: =C25/D$5 | F25: =(D25+E25)*2 | G25: =(D25+E25)*3 | H25: 1 | I25: =H25*F25 | J25: =F25 | K25: =G25 | L25: =G25 | M25: =G25 | N25: =SUM(J25:M25) | O25: =N25*O$5
A26: Production - Casuals | E26: =C26/D$5 | F26: =(D26+E26)*2 | G26: =(D26+E26)*3 | I26: =H26*F26 | J26: =F26 | K26: =F26 | L26: =G26 | M26: =G26 | N26: =SUM(J26:M26) | O26: =N26*O$5
A27: Location Manager(s) | E27: =C27/D$5 | F27: =(D27+E27)*2 | G27: =(D27+E27)*3 | I27: =H27*F27 | J27: =F27 | K27: =F27 | L27: =G27 | M27: =G27 | N27: =SUM(J27:M27) | O27: =N27*O$5
A28: Assistant Location Manager | D28: =C28/D$5 | F28: =(D28+E28)*2 | G28: =(D28+E28)*3 | H28: 2 | I28: =H28*F28 | J28: =G28 | K28: =G28 | L28: =G28 | M28: =G28 | N28: =SUM(J28:M28) | O28: =N28*O$5
A29: Unit Manager(s) | D29: =C29/D$5 | F29: =(D29+E29)*2 | G29: =(D29+E29)*3 | H29: 2 | I29: =H29*F29 | J29: =G29 | K29: =G29 | L29: =G29 | M29: =G29 | N29: =SUM(J29:M29) | O29: =N29*O$5
A30: Unit Assistant(s) | D30: =C30/D$5 | F30: =(D30+E30)*2 | G30: =(D30+E30)*3 | H30: 2 | I30: =H30*F30 | J30: =G30 | K30: =G30 | L30: =G30 | M30: =G30 | N30: =SUM(J30:M30) | O30: =N30*O$5
A31: Unit - Casuals | D31: =C31/D$5 | F31: =(D31+E31)*2 | G31: =(D31+E31)*3 | H31: 2 | I31: =H31*F31 | J31: =G31 | K31: =G31 | L31: =G31 | M31: =G31 | N31: =SUM(J31:M31) | O31: =N31*O$5
A32: Travel Co-ordinator | D32: =C32/D$5 | F32: =(D32+E32)*2 | G32: =(D32+E32)*3 | H32: 2 | I32: =H32*F32 | J32: =G32 | K32: =G32 | L32: =G32 | M32: =G32 | N32: =SUM(J32:M32) | O32: =N32*O$5
A33: Transport Manager | D33: =C33/D$5 | F33: =(D33+E33)*2 | G33: =(D33+E33)*3 | I33: =H33*F33 | J33: =F33 | K33: =F33 | L33: =G33 | M33: =G33 | N33: =SUM(J33:M33) | O33: =N33*O$5
A34: Transport Assistant | D34: =C34/D$5 | F34: =(D34+E34)*2 | G34: =(D34+E34)*3 | I34: =H34*F34 | J34: =F34 | K34: =F34 | L34: =G34 | M34: =G34 | N34: =SUM(J34:M34) | O34: =N34*O$5
A35: Driver(s) | E35: =C35/D$5 | F35: =(D35+E35)*2 | G35: =(D35+E35)*3 | I35: =H35*F35 | J35: =F35 | K35: =F35 | L35: =G35 | M35: =G35 | N35: =SUM(J35:M35) | O35: =N35*O$5
A36: Base Office Liaison | E36: =C36/D$5 | F36: =(D36+E36)*2 | G36: =(D36+E36)*3 | I36: =H36*F36 | J36: =F36 | K36: =F36 | L36: =G36 | M36: =G36 | N36: =SUM(J36:M36) | O36: =N36*O$5
A37: Financial Controller | E37: =C37/D$5 | F37: =(D37+E37)*2 | G37: =(D37+E37)*3 | I37: =H37*F37 | J37: =F37 | K37: =F37 | L37: =G37 | M37: =G37 | N37: =SUM(J37:M37) | O37: =N37*O$5
A38: Production Accountant | E38: =C38/D$5 | F38: =(D38+E38)*2 | G38: =(D38+E38)*3 | I38: =H38*F38 | J38: =F38 | K38: =F38 | L38: =G38 | M38: =G38 | N38: =SUM(J38:M38) | O38: =N38*O$5
A39: Accounts Assistant(s) | E39: =C39/D$5 | F39: =(D39+E39)*2 | G39: =(D39+E39)*3 | I39: =H39*F39 | J39: =F39 | K39: =F39 | L39: =G39 | M39: =G39 | N39: =SUM(J39:M39) | O39: =N39*O$5
A40: 1st Assistant Director | D40: =C40/D$5 | F40: =(D40+E40)*2 | G40: =(D40+E40)*3 | I40: =H40*F40 | J40: =F40 | K40: =F40 | L40: =G40 | M40: =G40 | N40: =SUM(J40:M40) | O40: =N40*O$5
...

Sheet 3.Cast
B1: 3. CAST FEES AND FRINGES SCHEDULE - TO BUDGET CATEGORIES D (Fringes) E(b) (Cast Below Line)
A2: CODE | B2: CHARACTER | C2: NAME/COMPANY | D2: PREPRODUCTION (incl.Rehearsals,W/D,M/U) | G2: SHOOT | L2: TOTAL FEES | M2: Super | N2: Payroll Tax | O2: Workers Comp | P2: TOTAL FRINGES
D3: B.N.F. Daily/Wkly | E3: No. Dys/Wks | F3: SUB-TOTAL | G3: Contract Rate Daily | H3: Contract Rate Wkly | I3: Days | J3: Weeks | K3: SUB-TOTAL | L3: C.2-5 | M3: D | N3: D | O3: D
C4: Calculation: | L4: F + K | M4: on total L | N4: on L+M | O4: on total L | P4: sum M to O
M5: 0.11 | N5: 0.0525 | O5: 0.01
A6: E(b)2 | B6: PRINCIPALS (refer Crossplot and Breakdown Sheet Nos.. ) | O6: (NSW)
B7: HELENA | F7: =D7*E7 | G7: =30.68*1.25*10 | H7: 1165.7 | I7: 5 | J7: 0 | K7: =(G7*I7)+(H7*J7) | L7: =F7+K7 | M7: =L7*M$5 | N7: =SUM(L7:M7)*N$5 | O7: =L7*O$5 | P7: =SUM(M7:O7)
B8: PIPPA | F8: =D8*E8 | G8: =30.68*1.25*10 | H8: 1165.7 | I8: 5 | J8: 0 | K8: =G8*I8+H8*J8 | L8: =F8+K8 | M8: =L8*M$5 | N8: =SUM(L8:M8)*N$5 | O8: =L8*O$5 | P8: =SUM(M8:O8)
B9: KIRSTY | F9: =D9*E9 | G9: =30.68*1.25*10 | H9: 1165.7 | I9: 2 | J9: 0 | K9: =G9*I9+H9*J9 | L9: =F9+K9 | M9: =L9*M$5 | N9: =SUM(L9:M9)*N$5 | O9: =L9*O$5 | P9: =SUM(M9:O9)
B10: BETH | E10: 0 | F10: =D10*E10 | G10: =30.68*1.25*10 | H10: 1165.7 | I10: 1 | K10: =G10*I10+H10*J10 | L10: =F10+K10 | M10: =L10*M$5 | N10: =SUM(L10:M10)*N$5 | O10: =L10*O$5 | P10: =SUM(M10:O10)
B11: Preprodn.incl Rehearsals,W/D,M/up | F11: =D11*E11 | G11: =30.68*1.25*10 | K11: =G11*I11+H11*J11 | L11: =F11+K11 | M11: =L11*M$5 | N11: =SUM(L11:M11)*N$5 | O11: =L11*O$5 | P11: =SUM(M11:O11)
B12: Audition Call-Backs | F12: =D12*E12 | G12: =30.68*1.25*10 | K12: =G12*I12+H12*J12 | L12: =F12+K12 | M12: =L12*M$5 | N12: =SUM(L12:M12)*N$5 | O12: =L12*O$5 | P12: =SUM(M12:O12)
B13: Shoot incl. travel days | F13: =D13*E13 | G13: =30.68*1.25*10 | K13: =G13*I13+H13*J13 | L13: =F13+K13 | M13: =L13*M$5 | N13: =SUM(L13:M13)*N$5 | O13: =L13*O$5 | P13: =SUM(M13:O13)
B14: Post-Sync | F14: =D14*E14 | G14: =30.68*1.25*10 | K14: =G14*I14+H14*J14 | L14: =F14+K14 | M14: =L14*M$5 | N14: =SUM(L14:M14)*N$5 | O14: =L14*O$5 | P14: =SUM(M14:O14)
B15: Hold-over Days | F15: =D15*E15 | G15: =30.68*1.25*10 | K15: =G15*I15+H15*J15 | L15: =F15+K15 | M15: =L15*M$5 | N15: =SUM(L15:M15)*N$5 | O15: =L15*O$5 | P15: =SUM(M15:O15)
B16: Allce for postponements, weather calls | F16: =D16*E16 | G16: =30.68*1.25*10 | K16: =G16*I16+H16*J16 | L16: =F16+K16 | M16: =L16*M$5 | N16: =SUM(L16:M16)*N$5 | O16: =L16*O$5 | P16: =SUM(M16:O16)
B17: Overtime | F17: =D17*E17 | G17: =30.68*1.25*10 | L17: =F17+K17 | M17: =L17*M$5 | N17: =SUM(L17:M17)*N$5 | O17: =L17*O$5 | P17: =SUM(M17:O17)
B18: Sub-total: | C18: Sub-total | F18: =SUM(F7:F17) | K18: =SUM(K7:K17) | L18: =SUM(L7:L17) | M18: =SUM(M7:M17) | N18: =SUM(N7:N17) | O18: =SUM(O7:O17) | P18: =SUM(P7:P17)
A20: E(b)3 | B20: SUPPORTS (refer Crossplot and Breakdown Sheet Nos.. )
B21: SUPPORT 1 | F21: =D21*E21 | G21: =35.03*10 | I21: 1 | K21: =G21*I21+H21*J21 | L21: =F21+K21 | M21: =L21*M$5 | N21: =SUM(L21:M21)*N$5 | O21: =L21*O$5 | P21: =SUM(M21:O21)
B22: SUPPORT 2 | F22: =D22*E22 | G22: =35.03*10 | I22: 1 | K22: =G22*I22+H22*J22 | L22: =F22+K22 | M22: =L22*M$5 | N22: =SUM(L22:M22)*N$5 | O22: =L22*O$5 | P22: =SUM(M22:O22)
B23: SUPPORT 3 | F23: =D23*E23 | G23: =35.03*10 | I23: 0 | K23: =G23*I23+H23*J23 | L23: =F23+K23 | M23: =L23*M$5 | N23: =SUM(L23:M23)*N$5 | O23: =L23*O$5 | P23: =SUM(M23:O23)
B24: SUPPORT 4 | F24: =D24*E24 | G24: =35.03*10 | I24: 0 | K24: =G24*I24+H24*J24 | L24: =F24+K24 | M24: =L24*M$5 | N24: =SUM(L24:M24)*N$5 | O24: =L24*O$5 | P24: =SUM(M24:O24)
B25: Preprodn.incl Rehearsals,W/D,M/up | F25: =D25*E25 | L25: =F25+K25 | M25: =L25*M$5 | N25: =SUM(L25:M25)*N$5 | O25: =L25*O$5 | P25: =SUM(M25:O25)
B26: Audition Call-Backs | F26: =D26*E26 | K26: =G26*I26+H26*J26 | L26: =F26+K26 | M26: =L26*M$5 | N26: =SUM(L26:M26)*N$5 | O26: =L26*O$5 | P26: =SUM(M26:O26)
B27: Shoot incl. travel days | F27: =D27*E27 | K27: =G27*I27+H27*J27 | L27: =F27+K27 | M27: =L27*M$5 | N27: =SUM(L27:M27)*N$5 | O27: =L27*O$5 | P27: =SUM(M27:O27)
B28: Post-Sync | F28: =D28*E28 | K28: =G28*I28+H28*J28 | L28: =F28+K28 | M28: =L28*M$5 | N28: =SUM(L28:M28)*N$5 | O28: =L28*O$5 | P28: =SUM(M28:O28)
B29: Hold-over Days | F29: =D29*E29 | K29: =G29*I29+H29*J29 | L29: =F29+K29 | M29: =L29*M$5 | N29: =SUM(L29:M29)*N$5 | O29: =L29*O$5 | P29: =SUM(M29:O29)
B30: Allce for postponements, weather calls | F30: =D30*E30 | K30: =G30*I30+H30*J30 | L30: =F30+K30 | M30: =L30*M$5 | N30: =SUM(L30:M30)*N$5 | O30: =L30*O$5 | P30: =SUM(M30:O30)
B31: Overtime | F31: =D31*E31 | K31: =G31*I31+H31*J31 | L31: =F31+K31 | M31: =L31*M$5 | N31: =SUM(L31:M31)*N$5 | O31: =L31*O$5 | P31: =SUM(M31:O31)
B32: Sub-total | C32: Sub-total | F32: =SUM(F21:F31) | K32: =SUM(K21:K31) | L32: =SUM(L21:L31) | M32: =SUM(M21:M31) | N32: =SUM(N21:N31) | O32: =SUM(O21:O31) | P32: =SUM(P21:P31)
A34: E(b)4 | B34: STANDINS & DOUBLES (refer Crossplot and Breakdown Sheet Nos.. )
F35: =D35*E35 | K35: =G35*I35+H35*J35 | L35: =F35+K35 | M35: =L35*M$5 | N35: =SUM(L35:M35)*N$5 | O35: =L35*O$5 | P35: =SUM(M35:O35)
F36: =D36*E36 | K36: =G36*I36+H36*J36 | L36: =F36+K36 | M36: =L36*M$5 | N36: =SUM(L36:M36)*N$5 | O36: =L36*O$5 | P36: =SUM(M36:O36)
F37: =D37*E37 | K37: =G37*I37+H37*J37 | L37: =F37+K37 | M37: =L37*M$5 | N37: =SUM(L37:M37)*N$5 | O37: =L37*O$5 | P37: =SUM(M37:O37)
F38: =D38*E38 | K38: =G38*I38+H38*J38 | L38: =F38+K38 | M38: =L38*M$5 | N38: =SUM(L38:M38)*N$5 | O38: =L38*O$5 | P38: =SUM(M38:O38)
F39: =D39*E39 | K39: =G39*I39+H39*J39 | L39: =F39+K39 | M39: =L39*M$5 | N39: =SUM(L39:M39)*N$5 | O39: =L39*O$5 | P39: =SUM(M39:O39)
B40: Hold-over Days | F40: =D40*E40 | K40: =G40*I40+H40*J40 | L40: =F40+K40 | M40: =L40*M$5 | N40: =SUM(L40:M40)*N$5 | O40: =L40*O$5 | P40: =SUM(M40:O40)
B41: Allce for postponements, weather calls | F41: =D41*E41 | K41: =G41*I41+H41*J41 | L41: =F41+K41 | M41: =L41*M$5 | N41: =SUM(L41:M41)*N$5 | O41: =L41*O$5 | P41: =SUM(M41:O41)
B42: Loadings | F42: =D42*E42 | K42: =G42*I42+H42*J42 | L42: =F42+K42 | M42: =L42*M$5 | N42: =SUM(L42:M42)*N$5 | O42: =L42*O$5 | P42: =SUM(M42:O42)
...

Sheet 4.Extr
C1: 4. EXTRAS FEES AND FRINGES SCHEDULE - TO BUDGET CATEGORIES D (Fringes) E.6 (Cast Below Line)
A2: SHOOT DAY | B2: SCENE NO. | C2: TYPE/ DESCRIPTION | D2: No. of Extras City/Country | E2: No. for 4 hr call | F2: Rate | G2: No. for 8 hr call | H2: Rate | I2: No. for 10 hr call | J2: Rate | K2: No.other/country | L2: Rate | M2: TOTAL FEES | N2: Super | O2: Payroll Tax | P2: Workers Comp | Q2: TOTAL FRINGES
D3: City FF Rates incl H.Pay:= | F3: 82.38 | H3: 137.3 | J3: 188.79 | M3: E.6 | N3: continuity extras only** | O3: D | P3: D
D4: Calculation: | O4: on total M+N | P4: on total M | Q4: sum N to P
N5: 0.09 | O5: 0.06 | P5: 0.011 | R5: **Superannuation is paid on $450 gross per month only
P6: (NSW) | R6: therefore usually only applies to extras who do more than 2 days
F7: =E7*F$3 | H7: =G7*H$3 | J7: =I7*J$3 | L7: =K7*L$3 | M7: =F7+H7+J7+L7 | O7: =SUM(M7:N7)*O$5 | P7: =M7*P$5 | Q7: =SUM(N7:P7)
C8: Extra | D8: 10 | E8: 4 | F8: =E8*F$3 | H8: =G8*H$3 | J8: =I8*J$3 | L8: =K8*L$3 | M8: =F8+H8+J8+L8 | O8: =SUM(M8:N8)*O$5 | P8: =M8*P$5 | Q8: =SUM(N8:P8)
F9: =E9*F$3 | H9: =G9*H$3 | J9: =I9*J$3 | L9: =K9*L$3 | M9: =F9+H9+J9+L9 | O9: =SUM(M9:N9)*O$5 | P9: =M9*P$5 | Q9: =SUM(N9:P9)
F10: =E10*F$3 | H10: =G10*H$3 | J10: =I10*J$3 | L10: =K10*L$3 | M10: =F10+H10+J10+L10 | O10: =SUM(M10:N10)*O$5 | P10: =M10*P$5 | Q10: =SUM(N10:P10)
F11: =E11*F$3 | H11: =G11*H$3 | J11: =I11*J$3 | L11: =K11*L$3 | M11: =F11+H11+J11+L11 | O11: =SUM(M11:N11)*O$5 | P11: =M11*P$5 | Q11: =SUM(N11:P11)
F12: =E12*F$3 | H12: =G12*H$3 | J12: =I12*J$3 | L12: =K12*L$3 | M12: =F12+H12+J12+L12 | O12: =SUM(M12:N12)*O$5 | P12: =M12*P$5 | Q12: =SUM(N12:P12)
F13: =E13*F$3 | H13: =G13*H$3 | J13: =I13*J$3 | L13: =K13*L$3 | M13: =F13+H13+J13+L13 | O13: =SUM(M13:N13)*O$5 | P13: =M13*P$5 | Q13: =SUM(N13:P13)
F14: =E14*F$3 | H14: =G14*H$3 | J14: =I14*J$3 | L14: =K14*L$3 | M14: =F14+H14+J14+L14 | O14: =SUM(M14:N14)*O$5 | P14: =M14*P$5 | Q14: =SUM(N14:P14)
F15: =E15*F$3 | H15: =G15*H$3 | J15: =I15*J$3 | L15: =K15*L$3 | M15: =F15+H15+J15+L15 | O15: =SUM(M15:N15)*O$5 | P15: =M15*P$5 | Q15: =SUM(N15:P15)
F16: =E16*F$3 | H16: =G16*H$3 | J16: =I16*J$3 | L16: =K16*L$3 | M16: =F16+H16+J16+L16 | O16: =SUM(M16:N16)*O$5 | P16: =M16*P$5 | Q16: =SUM(N16:P16)
F17: =E17*F$3 | H17: =G17*H$3 | J17: =I17*J$3 | L17: =K17*L$3 | M17: =F17+H17+J17+L17 | O17: =SUM(M17:N17)*O$5 | P17: =M17*P$5 | Q17: =SUM(N17:P17)
F18: =E18*F$3 | H18: =G18*H$3 | J18: =I18*J$3 | L18: =K18*L$3 | M18: =F18+H18+J18+L18 | O18: =SUM(M18:N18)*O$5 | P18: =M18*P$5 | Q18: =SUM(N18:P18)
F19: =E19*F$3 | H19: =G19*H$3 | J19: =I19*J$3 | L19: =K19*L$3 | M19: =F19+H19+J19+L19 | O19: =SUM(M19:N19)*O$5 | P19: =M19*P$5 | Q19: =SUM(N19:P19)
F20: =E20*F$3 | H20: =G20*H$3 | J20: =I20*J$3 | L20: =K20*L$3 | M20: =F20+H20+J20+L20 | O20: =SUM(M20:N20)*O$5 | P20: =M20*P$5 | Q20: =SUM(N20:P20)
... F34: =E34*F$3 | H34: =G34*H$3 | J34: =I34*J$3 | L34: =K34*L$3 | M34: =F34+H34+J34+L34 | O34: =SUM(M34:N34)*O$5 | P34: =M34*P$5 | Q34: =SUM(N34:P34)
C35: Totals | F35: =SUM(F7:F34) | H35: =SUM(H7:H34) | J35: =SUM(J7:J34) | L35: =SUM(L7:L34) | M35: =SUM(M7:M34) | N35: =SUM(N7:N34) | O35: =SUM(O7:O34) | P35: =SUM(P7:P34) | Q35: =SUM(Q7:Q34)
M37: Category E6 | N37: Total trf. to Category D | O37: Total trf. to Category D | P37: Total trf. to Category D
D39: NB. Annual leave is included in daily rate. Daily rates included in this spreadsheet are the rates for Feature film including annual leave as at March 2002.
E40: These should be adjusted as appropriate according to when you may expect to be shooting.

Sheet 5.Allce
A1: 5. CREW ALLOWANCES SCHEDULE - TO BUDGET CATEGORIES C and M or Department costs as applicable
A2: POSITION/Name | B2: TOOLS or EQUIP | E2: VEHICLE HIRE | I2: VEHICLE ALLOWANCES
B3: Rate | C3: No. Wks | D3: Total $ | E3: Description | F3: Days/Wks | G3: Rate | H3: Total $ | I3: Description | J3: Days/Wks | K3: Rate | L3: Total $
A4: Trf. To:
M5: Incl. Pre-prodn. And Shoot periods
A6: Producer(s) (ref.B.1)
A8: Director(s) (ref.B.2)
A10: Cast - Above Line (ref.E)
A13: CREW:
A15: Prodn. Managment | D15: =B15*C15 | H15: =F15*G15 | J15: 1 | K15: 50 | L15: =J15*K15
A16: Runner | D16: =B16*C16 | H16: =F16*G16 | L16: =J16*K16
A17: Loc. Man | D17: =B17*C17 | H17: =F17*G17 | L17: =J17*K17
A18: Prodn. Accountancy | D18: =B18*C18 | H18: =F18*G18 | L18: =J18*K18
D19: =B19*C19 | H19: =F19*G19 | L19: =J19*K19
D20: =B20*C20 | H20: =F20*G20 | L20: =J20*K20
A21: Asst.Directors/Script Supervision | D21: =B21*C21 | H21: =F21*G21 | K21: 50 | L21: =J21*K21
A22: 2nd A/D | D22: =B22*C22 | H22: =F22*G22 | K22: 50 | L22: =J22*K22
D23: =B23*C23 | H23: =F23*G23 | L23: =J23*K23
D24: =B24*C24 | H24: =F24*G24 | L24: =J24*K24
A25: Camera Crew | D25: =B25*C25 | H25: =F25*G25 | J25: 2 | K25: 50 | L25: =J25*K25
D26: =B26*C26 | H26: =F26*G26 | L26: =J26*K26
D27: =B27*C27 | H27: =F27*G27 | L27: =J27*K27
D28: =B28*C28 | H28: =F28*G28 | L28: =J28*K28
A29: Sound Crew | D29: =B29*C29 | H29: =F29*G29 | L29: =J29*K29
D30: =B30*C30 | H30: =F30*G30 | L30: =J30*K30
D31: =B31*C31 | H31: =F31*G31 | L31: =J31*K31
D32: =B32*C32 | H32: =F32*G32 | L32: =J32*K32
A33: Lighting Crew | D33: =B33*C33 | H33: =F33*G33 | L33: =J33*K33
D34: =B34*C34 | H34: =F34*G34 | L34: =J34*K34
D35: =B35*C35 | H35: =F35*G35 | L35: =J35*K35
D36: =B36*C36 | H36: =F36*G36 | L36: =J36*K36
A37: Grips Crew | D37: =B37*C37 | H37: =F37*G37 | L37: =J37*K37
D38: =B38*C38 | H38: =F38*G38 | L38: =J38*K38
D39: =B39*C39 | H39: =F39*G39 | L39: =J39*K39
D40: =B40*C40 | H40: =F40*G40 | L40: =J40*K40
D41: =B41*C41 | H41: =F41*G41 | L41: =J41*K41
D42: =B42*C42 | H42: =F42*G42 | L42: =J42*K42
D43: =B43*C43 | H43: =F43*G43 | L43: =J43*K43
A44: Make-up Crew | D44: =B44*C44 | H44: =F44*G44 | L44: =J44*K44
D45: =B45*C45 | H45: =F45*G45 | L45: =J45*K45
...

Sheet 6.Trav
A1: 6. CREW & CAST - TRAVEL & ACCOMMODATION SCHEDULE - TO BUDGET CATEGORIES M & N
A2: POSITION/Name | B2: AIRFARES/Other fares | E2: ACCOMMODATION or Allces | J2: PER DIEMS | O2: Catering | P2: Post-prodn. To Category T
B3: Rate | C3: No | D3: Total $ | E3: Rate pd | F3: Days | G3: Rate pwk | H3: Wks | I3: Total $ | J3: FullRate* | K3: Days | L3: Catered* | M3: Days | N3: Total $ | O3: Days | P3: * PDs vary according to provision of on-site catering
A4: Trf. To: | D4: M | I4: N | N4: N | O4: N
P5: Airfares in whole $ only.
A6: Producer(s) (ref.B.1)
P7: Use separate sheets for International and
A8: Director(s) (ref.B.2) | Q8: Australian locations or multiple sites
A10: Cast - Above Line (ref.E)
A13: CREW:
A15: Producer's Assistant(s) | D15: =B15*C15 | I15: =E15*F15+G15*H15 | N15: =J15*K15+L15*M15
A16: Director's Assistant | D16: =B16*C16 | I16: =E16*F16+G16*H16 | N16: =J16*K16+L16*M16
A17: Production Supervisor | D17: =B17*C17 | I17: =E17*F17+G17*H17 | N17: =J17*K17+L17*M17
A18: Production Manager | D18: =B18*C18 | I18: =E18*F18+G18*H18 | N18: =J18*K18+L18*M18
A19: Production Co-ordinator | D19: =B19*C19 | I19: =E19*F19+G19*H19 | N19: =J19*K19+L19*M19
A20: Production Secretary | D20: =B20*C20 | I20: =E20*F20+G20*H20 | N20: =J20*K20+L20*M20
A21: Production Assistant(s) | D21: =B21*C21 | I21: =E21*F21+G21*H21 | N21: =J21*K21+L21*M21
A22: Runner(s) | D22: =B22*C22 | I22: =E22*F22+G22*H22 | N22: =J22*K22+L22*M22
A23: Production - Casuals | D23: =B23*C23 | I23: =E23*F23+G23*H23 | N23: =J23*K23+L23*M23
A24: Location Manager(s) | D24: =B24*C24 | I24: =E24*F24+G24*H24 | N24: =J24*K24+L24*M24
A25: Assistant Location Manager | D25: =B25*C25 | I25: =E25*F25+G25*H25 | N25: =J25*K25+L25*M25
A26: Unit Manager(s) | D26: =B26*C26 | I26: =E26*F26+G26*H26 | N26: =J26*K26+L26*M26
... A167: Caterer 2 | D167: =B167*C167 | I167: =E167*F167+G167*H167 | N167: =J167*K167+L167*M167
D168: =B168*C168 | I168: =E168*F168+G168*H168 | N168: =J168*K168+L168*M168
D169: =B169*C169 | I169: =E169*F169+G169*H169 | N169: =J169*K169+L169*M169
A170: Offshore Unit | D170: =B170*C170 | I170: =E170*F170+G170*H170 | N170: =J170*K170+L170*M170
D171: =B171*C171 | I171: =E171*F171+G171*H171 | N171: =J171*K171+L171*M171
A172: Sub-total: | D172: =SUM(D15:D171) | I172: =SUM(I15:I171) | N172: =SUM(N15:N171) | O172: =SUM(O6:O171)
A175: CAST & EXTRAS:
A177: Cast - Principals | D177: =B177*C177 | I177: =E177*F177+G177*H177 | N177: =J177*K177+L177*M177
D178: =B178*C178 | I178: =E178*F178+G178*H178 | N178: =J178*K178+L178*M178
D179: =B179*C179 | I179: =E179*F179+G179*H179 | N179: =J179*K179+L179*M179
D180: =B180*C180 | I180: =E180*F180+G180*H180 | N180: =J180*K180+L180*M180
D181: =B181*C181 | I181: =E181*F181+G181*H181 | N181: =J181*K181+L181*M181
D182: =B182*C182 | I182: =E182*F182+G182*H182 | N182: =J182*K182+L182*M182
D183: =B183*C183 | I183: =E183*F183+G183*H183 | N183: =J183*K183+L183*M183
A184: Cast - Other | D184: =B184*C184 | I184: =E184*F184+G184*H184 | N184: =J184*K184+L184*M184
D185: =B185*C185 | I185: =E185*F185+G185*H185 | N185: =J185*K185+L185*M185
D186: =B186*C186 | I186: =E186*F186+G186*H186 | N186: =J186*K186+L186*M186
D187: =B187*C187 | I187: =E187*F187+G187*H187 | N187: =J187*K187+L187*M187
...

Sheet 7.Video
B1: 7. DIGITAL VIDEO PRODUCTION & POST-PRODN. COSTS - BUDGET CATEGORY J
B3: CREW - See Budget Category C | N3: Note: If budgeting for H.D.
B4: EQUIPMENT - See Budget Category K | N4: include line items as appropriate
B5: EDITING ROOMS - See Budget Category S
B6: SOUND EDIT & MIX - See Budget Categories U & V
B7: DELIVERY ITEMS - See Budget Category X.2 & Worksheet 11.
A8: Code | E8: Rate | G8: Footage/ Hrs/Rolls | K8: Discount if applicable | L8: Net Estimate | M8: TOTAL
K9: 0
C10: DIGITAL VIDEO SHOOT
C11: Video Stock:
D12: Camera Digital Stock | E12: 40 | F12: p.tape | G12: 10 | I12: =G12*E12 | K12: =-I12*K$9 | L12: =I12+K12
C13: Rushes transfer and dub
D14: Transfers - HD - DVD | E14: 100 | F14: p.hr | G14: 5 | I14: =G14*E14 | K14: =-I14*K$9 | L14: =I14+K14
D15: 16:9 - 4:3 conversion | F15: p.hr | I15: =G15*E15 | K15: =-I15*K$9 | L15: =I15+K15
D16: Rushes dubbing - VHS | F16: p.tape | I16: =G16*E16 | K16: =-I16*K$9 | L16: =I16+K16
D17: DVDstock | E17: 8 | F17: p.tape | G17: 0 | I17: =G17*E17 | K17: =-I17*K$9 | L17: =I17+K17
D18: Couriers | F18: p.day | I18: =G18*E18 | K18: =-I18*K$9 | L18: =I18+K18
C19: Off-line (see main budget)
C20: On-line Textless Master 16:9
D21: Digital Effects | F21: p.hr | I21: =G21*E21 | K21: =-I21*K$9 | L21: =I21+K21
D22: Character Generator | F22: p.hr | I22: =G22*E22 | K22: =-I22*K$9 | L22: =I22+K22
D23: Paint Box | F23: p.hr | I23: =G23*E23 | K23: =-I23*K$9 | L23: =I23+K23
D24: Conform Textless Master | F24: p.hr | I24: =G24*E24 | K24: =-I24*K$9 | L24: =I24+K24
D25: Testless Master stock | F25: p.tape | I25: =G25*E25 | K25: =-I25*K$9 | L25: =I25+K25
C26: Colour Correction
D27: Tape to Tape | F27: p.hr | I27: =G27*E27 | K27: =-I27*K$9 | L27: =I27+K27
D28: Transfer to Graded Master 16:9 | E28: 200 | F28: p.hr | G28: 1.5 | I28: =G28*E28 | K28: =-I28*K$9 | L28: =I28+K28
D29: Transfer to Graded Master 4:3 pan&scan | F29: p.hr | I29: =G29*E29 | K29: =-I29*K$9 | L29: =I29+K29
C30: On-line Texted Master
D31: Titles | F31: p.hr | I31: =G31*E31 | K31: =-I31*K$9 | L31: =I31+K31
D32: Conform Texted Master 16:9 | F32: p.hr
D33: Conform Texted Master 4:3 | F33: p.hr | I33: =G33*E33 | K33: =-I33*K$9 | L33: =I33+K33
D34: Titled Master stock | F34: p.tape | I34: =G34*E34 | K34: =-I34*K$9 | L34: =I34+K34
D35: Dub for sound (inc stock) | F35: p.tape | I35: =G35*E35 | K35: =-I35*K$9 | L35: =I35+K35
C36: Sound Editing & Mix (refer main budget)
D37: Audio Layback Digital Master | E37: 300 | F37: p.hr | G37: 1.5 | I37: =G37*E37 | K37: =-I37*K$9 | L37: =I37+K37
D38: Dolby 5.1 encoding | F38: p.hr | I38: =G38*E38 | K38: =-I38*K$9 | L38: =I38+K38
C39: Technical check
D40: Master 16:9 | F40: p.hr | I40: =G40*E40 | K40: =-I40*K$9 | L40: =I40+K40
D41: Master 4:3 | F41: p.hr | I41: =G41*E41 | K41: =-I41*K$9 | L41: =I41+K41
...

Sheet 8.Cost
A1: 8. COSTUME ESTIMATES - to BUDGET CATEGORY F.1
B2: CHARACTER NAME or Cast/Extra Nos. | D2: Script Day No. | E2: Scene No | F2: Costume requirements | H2: Estimated Cost | I2: TOTALS | J2: Comments
B45: Accessories/hats etc.
B48: Estimates for:
B49: Dry Cleaning
B50: Freight
B51: Repairs
B52: Expendables
B55: Allowance for Resale
B58: TOTAL TRANSFERRED TO CATEGORY F.1: | I58: =SUM(I3:I57)

Sheet 9.Art
A1: 9. ART DEPARTMENT ESTIMATES - TO BUDGET CATEGORIES H.1-7
A2: Scene No | B2: Set / Location NAME | C2: Description Day/Night | D2: Other detail | E2: Construction Materials (& Labour?) | F2: Props & Set Dressing | G2: Action Props & Vehicles | H2: Livestock (& Labour?) | I2: Sp. Fx | J2: Armoury | K2: Visual Fx (or U2) | L2: Animation & Puppetry | M2: TOTALS
B3: (Location costs - refer Worksheet 10) | E3: (Labour C14) | H3: (Labour C13) | N3: Ensure labour is covered in C or H.
M4: =SUM(E4:L4)
M5: =SUM(E5:L5)
M6: =SUM(E6:L6)
M7: =SUM(E7:L7)
M8: =SUM(E8:L8)
M9: =SUM(E9:L9)
M10: =SUM(E10:L10)
M11: =SUM(E11:L11)
M12: =SUM(E12:L12)
M13: =SUM(E13:L13)
M14: =SUM(E14:L14)
M15: =SUM(E15:L15)
... M61: =SUM(E61:L61)
B62: Totals | E62: =SUM(E4:E61) | F62: =SUM(F4:F61) | G62: =SUM(G4:G61) | H62: =SUM(H4:H61) | I62: =SUM(I4:I61) | J62: =SUM(J4:J61) | K62: =SUM(K4:K61) | L62: =SUM(L4:L61) | M62: =SUM(M4:M61) | N62: =SUM(E62:L62)
E63: transfer to H1 | F63: transfer to H2 | G63: transfer to H3 | H63: transfer to H4 | I63: transfer to H5 | J63: transfer to H5 | K63: transfer to H6 | L63: transfer to H7

Sheet 10.Locn
A1: 10. LOCATION & STAGE RENTAL COST ESTIMATES - TO BUDGET CATEGORIES G1.G2.
A2: Scene #'s | B2: Location NAME or VENUE/Stage | C2: Preprodn & Wrap Days/Wks | D2: SHOOT Days/Wks | E2: Total Days required | F2: Site rentals per day/wk | G2: Total Site Rental | H2: Council Fees per day/wk | I2: Total Council | J2: Security rate/hour | K2: Security hours | L2: Security Total | M2: Police Assistance | N2: Other | O2: TOTALS | P2: Refundable BONDS
E4: =SUM(C4:D4) | G4: =F4*E4 | I4: =E4*H4 | L4: =J4*K4 | O4: =G4+I4+L4+M4+N4
E5: =SUM(C5:D5) | G5: =F5*E5 | I5: =E5*H5 | L5: =J5*K5 | O5: =G5+I5+L5+M5+N5
E6: =SUM(C6:D6) | G6: =F6*E6 | I6: =E6*H6 | L6: =J6*K6 | O6: =G6+I6+L6+M6+N6
E7: =SUM(C7:D7) | G7: =F7*E7 | I7: =E7*H7 | L7: =J7*K7 | O7: =G7+I7+L7+M7+N7
E8: =SUM(C8:D8) | G8: =F8*E8 | I8: =E8*H8 | L8: =J8*K8 | O8: =G8+I8+L8+M8+N8
E9: =SUM(C9:D9) | G9: =F9*E9 | I9: =E9*H9 | L9: =J9*K9 | O9: =G9+I9+L9+M9+N9
E10: =SUM(C10:D10) | G10: =F10*E10 | I10: =E10*H10 | L10: =J10*K10 | O10: =G10+I10+L10+M10+N10
E11: =SUM(C11:D11) | G11: =F11*E11 | I11: =E11*H11 | L11: =J11*K11 | O11: =G11+I11+L11+M11+N11
E12: =SUM(C12:D12) | G12: =F12*E12 | I12: =E12*H12 | L12: =J12*K12 | O12: =G12+I12+L12+M12+N12
E13: =SUM(C13:D13) | G13: =F13*E13 | I13: =E13*H13 | L13: =J13*K13 | O13: =G13+I13+L13+M13+N13
E14: =SUM(C14:D14) | G14: =F14*E14 | I14: =E14*H14 | L14: =J14*K14 | O14: =G14+I14+L14+M14+N14
E15: =SUM(C15:D15) | G15: =F15*E15 | I15: =E15*H15 | L15: =J15*K15 | O15: =G15+I15+L15+M15+N15
... E33: =SUM(C33:D33) | G33: =F33*E33 | I33: =E33*H33 | L33: =J33*K33 | O33: =G33+I33+L33+M33+N33
B34: Totals | G34: =SUM(G4:G33) | I34: =SUM(I4:I33) | L34: =SUM(L4:L33) | M34: =SUM(M4:M33) | N34: =SUM(N4:N33) | O34: =SUM(O4:O33) | P34: =SUM(P4:P33)

Sheet 11.Del
A1: 11. DELIVERY REQUIREMENTS (& refer Category X.2 )
E2: Rate | G2: Footage/ Hrs/Rolls | H2: Sub-Total | I2: TOTAL
B4: FILM MATERIALS | K4: If EPK & Trailer production required
D5: Interpos | F5: p.ft | H5: =E5*G5 | K5: refer Worksheet 12 and insert totals
D6: Interdupe | F6: p.ft | H6: =E6*G6
D7: Release Print(s) | F7: p.ft | H7: =E7*G7
D8: Trailer (if not in U.1 Lab-Editing) | K8: and refer Worksheet 12.
D9: Sub-Total | H9: =SUM(H5:H8) | I9: =H9
B10: VIDEO MATERIALS
C11: Distribution Dubs
D12: Video Masters: | E12: No.of copies: | K12: Allow for copies to:
D13: HD 16:9 (USA) | F13: p.tape | H13: =E13*G13 | K13: Domestic Distributor
D14: HD 16:9 (Europe & Australia) | F14: p.tape | H14: =E14*G14 | K14: Foreign Sales Agent
D15: HD 4x3 (USA) | F15: p.tape | H15: =E15*G15 | K15: Domestic Pay TV
D16: HD 4x3 (Europe & Australia) | F16: p.tape | H16: =E16*G16 | K16: Domestic Free to Air
D17: SD 16:9 (Digital Betacam NTSC) | F17: p.tape | H17: =E17*G17 | K17: Production Company
D18: SD 16:9 (Digital Betacam PAL) | F18: p.tape | H18: =E18*G18 | K18: Federal Funding Body
D19: SD 4x3 (Digital Betacam NTSC) | F19: p.tape | H19: =E19*G19 | K19: State Funding Body
D20: SD 4x3 (Digital Betacam PAL) | F20: p.tape | H20: =E20*G20 | K20: Screensound Archives
D21: Stock Costs | F21: p.tape | H21: =E21*G21 | K21: Other…
D22: Aspect Ratio Converter | F22: p.hr | H22: =E22*G22
D23: Transfer Time | F23: p.hr | H23: =E23*G23
D24: Sub-Total | H24: =SUM(H13:H23) | I24: =H24
C25: Additional Dubs
D26: VHS - PAL | F26: p.tape | H26: =E26*G26
D27: U-Matic - PAL | F27: p.tape | H27: =E27*G27 | K27: Copies as above
D28: VHS - NTSC 16:9 | F28: p.tape | H28: =E28*G28
D29: VHS - NTSC 4x3 | F29: p.tape | H29: =E29*G29
D30: U-Matic - NTSC | F30: p.tape | H30: =E30*G30
D31: DVD - multiregion | E31: 250 | F31: p.hr | G31: 1 | H31: =E31*G31
D32: Sub-Total | H32: =SUM(H26:H31) | I32: =H32
C33: Labour and Facilities - or refer Worksheet 12 - EPK & Trailer Production
D34: Trailer Editor (if not included in R or U) | F34: p.hr | H34: =E34*G34
D35: Cutting Room | F35: p.hr | H35: =E35*G35
D36: Telecine & Grade | F36: p.hr | H36: =E36*G36
D37: On-line | F37: p.hr | H37: =E37*G37
D38: Sub-Total | H38: =SUM(H34:H37) | I38: =H38
B39: SOUND REQUIREMENTS
D40: Copy of Final Mix | H40: =E40*G40
D41: Copy M&E | H41: =E41*G41
...

Sheet 12.EPK
A1: 12. EPK and/or TRAILER PRODN - DELIVERY REQUIREMENTS (& refer Categories U. V. X.)
E2: Rate | G2: Hrs/Rolls | H2: Sub-Total | I2: TOTAL
B4: Also use this Worksheet if a 'Behind the Scenes' Documentary is required
C6: Crew & Talent
D7: D.o.P. | H7: =E7*G7
D8: Camera Assistant | H8: =E8*G8
D9: Sound Recordist | H9: =E9*G9
D10: Gaffer | H10: =E10*G10
D11: Make-up | H11: =E11*G11
D12: Costumes | H12: =E12*G12
D13: Production Assistant | H13: =E13*G13
D14: Editor | H14: =E14*G14
D15: Sound Editor | H15: =E15*G15
D16: Talent - Voice Over | H16: =E16*G16
D17: Subtotal | H17: =SUM(H7:H16)
D18: Allow Fringes
D19: Sub-total | H19: =SUM(H17:H18) | I19: =H19
C20: Equipment & Stock
D21: Camera | H21: =E21*G21
D22: Sound | H22: =E22*G22
D23: Lighting | H23: =E23*G23
D24: Tape Stock - Video | H24: =E24*G24
D25: Tape Stock - Sound | H25: =E25*G25
D26: Sub-total | H26: =SUM(H21:H25) | I26: =H26
C27: Editing & Sound
D28: Rushes Transfers | H28: =E28*G28
D29: Off-line Editing Equipment | H29: =E29*G29
D30: On-line Editing | H30: =E30*G30
D31: Tape to Tape Grade | H31: =E31*G31
D32: Titles/Collage | H32: =E32*G32
D33: Mastering | H33: =E33*G33
D34: Re-stripe | H34: =E34*G34
D35: Tape Stock - sub-master, Master. | H35: =E35*G35
H36: =E36*G36
D37: Sound Editing Equipment | H37: =E37*G37
D38: Music Lay-up | H38: =E38*G38
D39: Sound Mix | H39: =E39*G39
D40: Sound Masters | H40: =E40*G40
D41: Sub-total | H41: =SUM(H28:H40) | I41: =H41
C42: Dubs
...

Sheet 13.Mktg
A1: 13. MARKETING - Post production (if not incl. In Delivery Requirements)
E2: Rate | G2: Footage/ Hrs/Rolls | H2: Sub-Total | I2: TOTAL
B3: Publicity & Stills - Shoot & Post-prodn - Budget Category X.1
B4: EPK - May be included in Delivery Requirements
B6: 1. PUBLICITY MATERIALS
C7: a. Publicist (if required)
D8: Fees
C9: b. Stills
D10: Stills Cameraperson (if required)
D11: Stock & Processing
D12: Transparencies
D13: Prints
C14: c. Press Kits
D15: EPK - see d.below
D16: Cover
D17: Typing
D18: Artwork
D19: Printing
D20: Distribution
C21: d. Electronic Press Kit (refer Worksheet 12)
D22: Production
D23: Copies
D24: Distribution
C25: e. Promotional Materials
D26: Artwork
D27: Printing
D28: Fliers
D29: Postcards
D30: Poster
D31: Distribution
D32: Other
C33: f. Video Promo
D34: Production
D35: Copies
D36: Distribution
C37: g. Other
D39: Sub-total | H39: =SUM(H7:H38) | I39: =H39
B41: 2. OFFICE & PRODUCTION EXPENSES
D42: Office
D43: Telephone/Fax
...

Sheet 14.Fringe
A1: 14. CREW FRINGES SCHEDULE - TO BUDGET CATEGORY D (Accountant to prepare for final budget)
A2: POSITION | B2: NAME/COMPANY | C2: Weekly Rate | D2: Wks | E2: Total Wages | F2: M/V.Allce | G2: Equip Allce | H2: Other - PDs. | I2: Hol.Pay | J2: Payroll Tax | K2: Super | L2: Workers Comp | M2: TOTAL FRINGES
B3: Calculation: | E3: D*E | F3: Rate*E | G3: Rate*E | I3: on total E | J3: on E to I+K | K3: on total E-H | L3: on E to G+I | M3: sum I to L
I4: =1/12 | J4: 0.06 | K4: 0.09 | L4: 0.011 | N4: Check the rate for payroll tax and workers compensation for the states in which you intend to shoot.
J5: (State rate?) | L5: (State rate?)
A6: Producer - if applicable, Hol.Pay and Super to B1 | E6: =C6*D6 | I6: =E6*I$4 | J6: =(SUM(E6:I6)+K6)*J$4 | K6: =SUM(E6:H6)*K$4 | L6: =(SUM(E6:G6)+I6)*L$4 | M6: =SUM(I6:L6) | N6: Above Line costs
A7: Director - if applicable Hol.Pay and Super to B2 | E7: =C7*D7 | I7: =E7*I$4 | J7: =(SUM(E7:I7)+K7)*J$4 | K7: =SUM(E7:H7)*K$4 | L7: =(SUM(E7:G7)+I7)*L$4 | M7: =SUM(I7:L7) | N7: Above Line costs
A9: Producer's Assistant(s) | E9: =C9*D9 | I9: =E9*I$4 | J9: =(SUM(E9:I9)+K9)*J$4 | K9: =SUM(E9:H9)*K$4 | L9: =(SUM(E9:G9)+I9)*L$4 | M9: =SUM(I9:L9)
A10: Director's Assistant | E10: =C10*D10 | I10: =E10*I$4 | J10: =(SUM(E10:I10)+K10)*J$4 | K10: =E10*K$4 | L10: =(SUM(E10:G10)+I10)*L$4 | M10: =SUM(I10:L10)
A11: Production Supervisor | E11: =C11*D11 | I11: =E11*I$4 | J11: =(SUM(E11:I11)+K11)*J$4 | K11: =E11*K$4 | L11: =(SUM(E11:G11)+I11)*L$4 | M11: =SUM(I11:L11)
A12: Production Manager | E12: =C12*D12 | I12: =E12*I$4 | J12: =(SUM(E12:I12)+K12)*J$4 | K12: =E12*K$4 | L12: =(SUM(E12:G12)+I12)*L$4 | M12: =SUM(I12:L12)
A13: Production Co-ordinator | E13: =C13*D13 | I13: =E13*I$4 | J13: =(SUM(E13:I13)+K13)*J$4 | K13: =E13*K$4 | L13: =(SUM(E13:G13)+I13)*L$4 | M13: =SUM(I13:L13)
A14: Production Secretary | E14: =C14*D14 | I14: =E14*I$4 | J14: =(SUM(E14:I14)+K14)*J$4 | K14: =E14*K$4 | L14: =(SUM(E14:G14)+I14)*L$4 | M14: =SUM(I14:L14)
A15: Production Assistant(s) | E15: =C15*D15 | I15: =E15*I$4 | J15: =(SUM(E15:I15)+K15)*J$4 | K15: =E15*K$4 | L15: =(SUM(E15:G15)+I15)*L$4 | M15: =SUM(I15:L15)
A16: Runner(s) | E16: =C16*D16 | I16: =E16*I$4 | J16: =(SUM(E16:I16)+K16)*J$4 | K16: =E16*K$4 | L16: =(SUM(E16:G16)+I16)*L$4 | M16: =SUM(I16:L16)
A17: Production - Casuals | E17: =C17*D17 | I17: =E17*I$4 | J17: =(SUM(E17:I17)+K17)*J$4 | K17: =E17*K$4 | L17: =(SUM(E17:G17)+I17)*L$4 | M17: =SUM(I17:L17)
A18: Location Manager(s) | E18: =C18*D18 | I18: =E18*I$4 | J18: =(SUM(E18:I18)+K18)*J$4 | K18: =E18*K$4 | L18: =(SUM(E18:G18)+I18)*L$4 | M18: =SUM(I18:L18)
A19: Assistant Location Manager | E19: =C19*D19 | I19: =E19*I$4 | J19: =(SUM(E19:I19)+K19)*J$4 | K19: =E19*K$4 | L19: =(SUM(E19:G19)+I19)*L$4 | M19: =SUM(I19:L19)
A20: Unit Manager(s) | E20: =C20*D20 | I20: =E20*I$4 | J20: =(SUM(E20:I20)+K20)*J$4 | K20: =E20*K$4 | L20: =(SUM(E20:G20)+I20)*L$4 | M20: =SUM(I20:L20)
A21: Unit Assistant(s) | E21: =C21*D21 | I21: =E21*I$4 | J21: =(SUM(E21:I21)+K21)*J$4 | K21: =E21*K$4 | L21: =(SUM(E21:G21)+I21)*L$4 | M21: =SUM(I21:L21)
... A157: Overtime | E157: =C157*D157 | I157: =E157*I$4 | J157: =(SUM(E157:I157)+K157)*J$4 | K157: =E157*K$4 | L157: =(SUM(E157:G157)+I157)*L$4 | M157: =SUM(I157:L157)
A158: TOTAL FOR ALL CREW: | E158: =SUM(E9:E157) | F158: =SUM(F9:F157) | G158: =SUM(G9:G157) | H158: =SUM(H9:H157) | I158: =SUM(I9:I157) | J158: =SUM(J9:J157) | K158: =SUM(K9:K157) | L158: =SUM(L9:L157) | M158: =SUM(M9:M157) | N158: =SUM(F158:L158) | O158: check.
A159: (excl.Producer & Director)
A161: D. | B161: TOTAL AUSTRALIAN FRINGES - CREW: (Category D)
B162: Holiday Pay - Crew | E162: =I158
B163: Payroll Tax - Producer/Director if applicable
B164: Payroll Tax - Crew | E164: =J158
B165: Payroll Tax on Overtime est.
B166: Apply threshold x mths. in production to Category D summary | F166: NB.
B167: Superannuation - Crew | E167: =K158
B168: Superannuation - Producer/Director if applicable to B1&2.
B169: Workers Compensation - Producer/Director
B170: Workers Compensation | E170: =L158
B171: Workers Compensation on Overtime est.

Sheet Summary
A1: BUDGET SUMMARY | C1: =Cover!D3 | H1: Check Col.$Aust.
B2: as at: | C2: 42984 | D2: $Australian | F2: Currency……. | H2: If conversion required adjust
B3: prepared by | C3: Melissa Johnston | D3: Trf.from A-Z | E3: TOTALS | F3: Convert at: | G3: =Cover!G60 | H3: print area to incl. Cols F&G | I3: Rate per cover sheet
A4: "ABOVE THE LINE" COSTS | H4: (and change page set-up)
A5: A.1 | B5: STORY & SCRIPT | C5: Fees & Expenses | D5: =Budget!M7 | F5: =D5*G$3
A6: A.2 | B6: DEVELOPMENT | C6: Fees & Expenses | D6: =Budget!M12 | E6: =D5+D6 | F6: =D6*G$3 | G6: =F5+F6
A7: B.1 | B7: PRODUCERS | C7: Fees & Expenses | D7: =Budget!M18 | F7: =D7*G$3
A8: B.2 | B8: DIRECTORS | C8: Fees & Expenses | D8: =Budget!M26 | E8: =D7+D8 | F8: =D8*G3 | G8: =F7+F8
A9: E(a) | B9: CAST-PRINCIPALS | C9: Fees & Expenses | E9: =Budget!#REF! | G9: =E9*G$3
B10: TOTAL "ABOVE THE LINE" COSTS | E10: =SUM(E5:E9) | G10: =SUM(G5:G9) | H10: =Budget!M28
A11: "BELOW THE LINE" COSTS
A12: PRODUCTION COSTS
A13: C | B13: UNIT FEES & SALARIES
A14: 1 | C14: Production Management | D14: =Budget!M37 | F14: =D14*G$3
A15: 2 | C15: Production Accountancy | D15: =Budget!M40 | F15: =D15*G$3
A16: 3 | C16: Asst.Directors & Script Supervision | D16: =Budget!M43 | F16: =D16*G$3
A17: 4 | C17: Camera Crew | D17: =Budget!M47 | F17: =D17*G$3
A18: 5 | C18: Sound Crew | D18: =Budget!M51 | F18: =D18*G$3
A19: 6 | C19: Lighting Crew | D19: =Budget!M54 | F19: =D19*G$3
A20: 7 | C20: Grips Crew | D20: =Budget!M57 | F20: =D20*G$3
A21: 8 | C21: Costume Crew | D21: =Budget!M62 | F21: =D21*G$3
A22: 9 | C22: Make-up Crew | D22: =Budget!M66 | F22: =D22*G$3
A23: 10 | C23: Hairdressing Crew | D23: =Budget!#REF! | F23: =D23*G$3
A24: 11 | C24: Art Department Crew | D24: =Budget!M71 | F24: =D24*G$3
A25: 12 | C25: Action Vehicles Crew | D25: =Budget!#REF! | F25: =D25*G$3
A26: 13 | C26: Livestock Crew | D26: =Budget!#REF! | F26: =D26*G$3
A27: 14 | C27: Construction Crew | D27: =Budget!M75 | F27: =D27*G$3
A28: 15 | C28: Special Effects & Armoury Crew | D28: =Budget!#REF! | F28: =D28*G$3
A29: 16 | C29: Visual Effects & Animation | D29: =Budget!#REF! | F29: =D29*G$3
A30: 17 | C30: Occupational Health & Safety Crew | D30: =Budget!M78 | F30: =D30*G$3
A31: 18 | C31: Tuition & Technical Advisers | D31: =Budget!#REF! | F31: =D31*G$3
A32: 19 | C32: Second Unit Crew | D32: =Budget!#REF! | F32: =D32*G$3
A33: 20 | C33: Offshore Unit Crew | D33: =Budget!#REF! | F33: =D33*G$3
A34: 24 | C34: Overtime & Loadings | D34: =Budget!M81 | F34: =D34*G$3
B35: Total Unit Fees & Salaries: | E35: =SUM(D13:D34) | G35: =SUM(F13:F34) | H35: =Budget!M82
A36: D | B36: FRINGES & WORKERS COMP - CREW/CAST | E36: =Budget!M116 | G36: =E36*G$3
A37: E(b) | B37: CAST & CASTING
A38: 1 | C38: Casting Fees & Expenses | D38: =Budget!#REF! | F38: =D38*G$3
A39: 2 | C39: Principals | D39: =Budget!M120 | F39: =D39*G$3
A40: 3 | C40: Supports | D40: =Budget!M123 | F40: =D40*G$3
...
